<mujoco model="jaco2">
    <compiler angle="radian" meshdir="meshes" balanceinertia="true"/>

    <default>
        <light castshadow="false" diffuse="1 1 1" />
        <camera fovy="60" />
    </default>

  <!--custom>
        <numeric name="START_ANGLES" data="2.0 3.14 1.57 4.71 0.0 3.04" />
        <numeric name="N_GRIPPER_JOINTS" data="3" />
        <text name="google_id" data="1doam-DgkW7OSPnwWZQM84edzX84ot-GK" />
    </custom-->

    <asset>
        <!-- arm models -->
        <mesh file="link0.stl" scale="5.0 5.0 5.0"/>
        <mesh file="link1.stl" scale="5.0 5.0 5.0"/>
        <mesh file="link2.stl" scale="5.0 5.0 5.0"/>
        <mesh file="link3.stl" scale="5.0 5.0 5.0"/>
        <mesh file="link4_5.stl" scale="5.0 5.0 5.0"/>
        <mesh file="hand_3finger.stl" scale="5.0 5.0 5.0"/>
        <mesh file="finger_distal.stl" scale="5.0 5.0 5.0"/>
        <mesh file="finger_proximal.stl" scale="5.0 5.0 5.0"/>
        <mesh file="ring_big.stl" scale="5.0 5.0 5.0"/>
        <mesh file="ring_small.stl" scale="5.0 5.0 5.0"/>

        <texture name="floor_tile" file="meshes/floor_tile.png" width="3000" height="3000" type="2d"/>
        <material name="tile" texture="floor_tile" specular="0" shininess="0" reflectance="0" emission="1" />

        <material name="carbon" specular="1" shininess="1" reflectance="1" rgba="0.05 0.05 0.05 1" emission="1" />
        <material name="grey_plastic" specular="0.5" shininess="0" reflectance="0" rgba="0.12 0.14 0.14 1" emission="1" />

        <texture name="abr_logo" file="meshes/abr_logo.png" width="193" height="193" type="2d"/>
        <material name="logo" texture="abr_logo"/>

        <texture name="abr_logo_flip" file="meshes/abr_logo.png" width="193" height="193" type="2d" hflip="true"/>
        <material name="logo_flip" texture="abr_logo_flip"/>

        <texture name="foam_blocks" file="meshes/foam_blocks.png" width="2744" height="2744" type="2d"/>
        <material name="foam" texture="foam_blocks" specular="0" shininess="0" reflectance="0" emission="1" />

    </asset>

    <worldbody>
      <!-- <geom name="floor_foam_block" pos="0.0 0.0 0.0" size="2.5 2.5 0.25" type="plane" rgba="1 0.83 0.61 1" material="foam"/>
        <geom name="floor_grey_tile" pos="0.0 0.0 -0.005" size="3.75 3.75 0.25" type="plane" material="tile"/> -->

        <!-- control visualizations -->
        <body name="hand" pos="0.0 0.0 -0.75" mocap="true">
            <geom type="box" size="0.01 0.02 0.03" rgba="0 .9 0 .5" contype="2" conaffinity="2"/>
        </body>

        <body name="target" pos="0.0 0.0 -0.75" mocap="true">
            <geom name="target" type="sphere" size="0.25" rgba=".9 0 0 .5" contype="4" conaffinity="4"/>
        </body>

        <body name="target_orientation" pos="0.0 0.0 -0.75" mocap="true">
            <geom type="box" size="0.1 0.2 0.3" rgba=".9 0 0 .5" contype="8" conaffinity="8"/>
        </body>

        <body name="path_planner" pos="0.0 0.0 -0.75" mocap="true">
            <geom type="sphere" size="0.25" rgba="0 1 1 0.5" contype="16" conaffinity="16"/>
        </body>

        <body name="path_planner_orientation" pos="0.0 0.0 -0.75" mocap="true">
            <geom type="box" size="0.1 0.2 0.3" rgba="0 1 1 .5" contype="32" conaffinity="32"/>
        </body>

        <body name="obstacle" pos="0.0 0.0 -0.75" mocap="true">
            <geom type="sphere" size="0.25" rgba="0 0 1 1"/>
        </body>

        <light directional="true" pos="-2.5 2.5 15.0" dir="0 0 -1" />

        <body name="base_link" pos="0.0 0.0 0.0">
            <geom name="link0" type="mesh" mesh="link0" pos="0.0 0.0 0.0" material="carbon"/>
            <inertial pos="0.0 0.0 0.6275" mass="1.226" diaginertia="0.25 0.25 0.25"/>
            <geom type="sphere" size="0.125" pos="0.0 0.0 0.6275" rgba="1 0.5 0 1"/>

            <body name="link1" pos="0.0 0.0 0.785" >
                <inertial pos="-0.00020999999999999998 -0.006424999999999999 0.56392" mass="0.754000" diaginertia="0.3 0.3 0.3"/>
                <geom name="link1" type="mesh" mesh="link1" pos="0.0 0.0 0.0" euler="0 3.14 0" material="carbon" />
                <!-- <geom name="ring0" type="mesh" mesh="ring_big" material="grey_plastic"/> -->
                <geom name="joint_logo0" type="cylinder" size="0.032 0.005" material="logo" pos="0.0 -0.182 0.593" euler="1.6 0 0"/>
                <joint name="joint0" axis="0 0 -1" pos="-0.0 -0.0 -0.0" range="-6.28 6.28" damping="1000" stiffness="1000" springref="0.0"/>

                <body name="link2" pos="0.0 0.008 0.593" euler="0 0.785 0">
                    <inertial pos="7e-05 0.046765 1.6450300000000002" mass="1.010000" diaginertia="0.3 0.3 0.3"/>
                    <geom name="link2" type="mesh" mesh="link2" pos="0.0 0.0 0.0" euler="1.57 0 3.14" material="carbon"/>
                    <geom name="ring1" type="mesh" mesh="ring_big" material="grey_plastic" euler="1.57 0 0"/>
                    <geom name="joint_logo1" type="cylinder" size="0.032 0.005" material="logo_flip" pos="0.0 0.19 0.0" euler="1.52 0 0"/>
                    <geom name="joint_logo2" type="cylinder" size="0.032 0.005" material="logo_flip" pos="0.0 0.1925 2.05" euler="1.62 0 0"/>
                    <joint name="joint1" pos="0 0 0" axis="0 -1 0"  ref="0" limited="true" range="-3.14 3.14" damping="1000" stiffness="1000" springref="0.0"/>

                    <body name="link3" pos="0.0 0.0 2.05" euler="0 1.57 0">
                        <inertial pos="-0.000195 -0.09034500000000001 0.76635" mass="0.559000" diaginertia="0.275 0.275 0.275"/>
                        <geom name="link3" type="mesh" mesh="link3" pos="0.0 0.0 0.0" euler="1.57 3.14 0" material="carbon"/>
                        <geom name="ring2" type="mesh" mesh="ring_big" material="grey_plastic" euler="1.57 0 0"/>
                        <joint name="joint2" pos="0.0 0.0 0.0" axis="0 1 0" ref="0" limited="true" range="-3.14 3.14" damping="1000" stiffness="1000" springref="0.0"/>
                        <geom name="joint_logo3" type="cylinder" size="0.032 0.005" material="logo" pos="0.0 -0.19 0.0" euler="1.54 0 0"/>

                        <body name="link4" pos="0.0 -0.057499999999999996 1.036" euler="0 0.785 0">
                            <inertial pos="0.0 0.16151 0.298525" mass="0.417000" diaginertia="0.175 0.175 0.175"/>
                            <geom name="link4" type="mesh" mesh="link4_5" euler="3.14 0 0" material="carbon"/>
                            <geom name="ring3" type="mesh" mesh="ring_small" material="grey_plastic"/>
                            <joint name="joint3" pos="0.0 0.0 0.0" axis="0 0 -1" ref="0" damping="1000" stiffness="1000" springref="0.0" range="-6.28 6.28"/>

                            <body name="link5" pos="0.0 0.185 0.3205" euler="0 0 0">
                                <inertial pos="-0.0 0.177725 0.289165" mass="0.417" diaginertia="0.175 0.175 0.175"/>
                                <geom name="link5" type="mesh" mesh="link4_5" euler="-1.0472 3.14 0" material="carbon"/>
                                <geom name="ring4" type="mesh" mesh="ring_small" material="grey_plastic" euler="-1.0471 0 0"/>
                                <joint name="joint4" pos="0.0 0.0 0.0" axis="0 -1.9 -1.1" ref="0" damping="1000" stiffness="1000" springref="0.0"/>

                                <body name="link6" pos="0.0 0.185 0.3205" >
                                    <inertial pos="0.00015000000000000001 -0.0342 0.4111" mass="0.727000" diaginertia="0.025 0.025 0.025"/>
                                    <geom name="link6" type="mesh" mesh="hand_3finger" euler="3.14 0 0" material="carbon" solimp="0.97 0.97 0.01" solref="0.01 1" condim="6" />
                                    <geom name="ring5" type="mesh" mesh="ring_small" material="grey_plastic"/>
                                    <joint name="joint5" pos="0.0 0.0 0.0" axis="0 0 -1" ref="0" range="-6.28 6.28" damping="1000" stiffness="1000" springref="0.0" />
                                    <!-- for fingertip EE -->
                                    <body name="EE" pos="0.0 0.0 0.6" euler="0 0 0">
                                    </body>

                                    <!-- for palm EE -->
                                    <!-- body name="EE" pos="0.0 0.0 0.6" euler="0 0 0">
                                    </body-->

                                    <body name="thumb_proximal" pos="0.01393 -0.15630000000000002 0.5733400000000001" quat="0.95922726  0.262085    0.02762996 -0.10213274">
                                        <geom name="thumb_proximal" type="mesh" mesh="finger_proximal" euler="0 -1.5707 0" friction="1 0.5 0.01" solimp="0.95 0.95 0.01 0.5 6" solref="0.01 1" condim="6" margin="0.0"/>
                                        <joint name="joint_thumb" pos="0.0 0.0 0.0" axis="1 0 0" ref="1.1" limited="true" range="-0.2 1.1" solimplimit="0.95 0.95 0.01" solreflimit="0.01 1" stiffness="5" springref="0.0" damping="0.35"/>

                                        <body name="thumb_distal" pos="0.0 -0.015 0.21999999999999997">
                                            <geom name="thumb_distal" type="mesh" mesh="finger_distal" euler="0 -1.5707 0" friction="1 0.5 0.01" solimp="0.95 0.95 0.01 0.5 6" solref="0.01 1" condim="6" margin="0.0"/>
                                            <joint name="joint_thumb_distal" pos="0.0 0.0 0.0" axis="-1 0 0" ref="0" limited="true" range="-0.4 0.4" stiffness="5" springref="-0.4" damping="0.5" solimplimit="0.95 0.95 0.01" solreflimit="0.01 1"/>
                                        </body>
                                    </body>

                                    <body name="index_proximal" pos="0.11128 0.135365 0.5733400000000001" quat="0.96181018 -0.25771638 0.0238668 -0.08907205">
                                        <geom name="index_proximal" type="mesh" mesh="finger_proximal" quat="5.63312174e-04  7.06824957e-01 -5.62863772e-04  7.07388045e-01" friction="1 0.5 0.01" solimp="0.95 0.95 0.01 0.5 6" solref="0.01 1" condim="6" margin="0.0"/>
                                        <joint name="joint_index" pos="0.0 0.0 0.0" axis="-1 0 0" ref="1.1" limited="true" range="-0.2 1.1" solimplimit="0.95 0.95 0.01" solreflimit="0.01 1" stiffness="5" springref="0.0" damping="0.35"/>

                                        <body name="index_distal" pos="0.0 0.015 0.21999999999999997">
                                            <geom name="index_distal" type="mesh" mesh="finger_distal" quat="5.63312174e-04  7.06824957e-01 -5.62863772e-04  7.07388045e-01" friction="1 0.5 0.01" solimp="0.95 0.95 0.01 0.5 6" solref="0.01 1" condim="6" margin="0.0"/>
                                            <joint name="joint_index_distal" pos="0.0 0.0 0.0" axis="1 0 0" ref="0" limited="true" range="-0.4 0.4" stiffness="5" springref="-0.4" damping="0.5" solimplimit="0.95 0.95 0.01" solreflimit="0.01 1"/>
                                        </body>
                                    </body>

                                    <body name="pinky_proximal" pos="-0.11128 0.135365 0.57408" quat="0.96181018 -0.25771638 -0.0238668 0.08907205">
                                        <geom name="pinky_proximal" type="mesh" mesh="finger_proximal" quat="5.63312174e-04  7.06824957e-01 -5.62863772e-04  7.07388045e-01" friction="1 0.5 0.01" solimp="0.95 0.95 0.01 0.5 6" solref="0.01 1" condim="6" margin="0.0"/>
                                        <joint name="joint_pinky" pos="0.0 0.0 0.0" axis="-1 0 0" ref="1.1" limited="true" range="-0.2 1.1" solimplimit="0.95 0.95 0.01" solreflimit="0.01 1" stiffness="5" springref="0.0" damping="0.35"/>

                                        <body name="pinky_distal" pos="0.0 0.015 0.21999999999999997">
                                            <geom name="pinky_distal" type="mesh" mesh="finger_distal" quat="5.63312174e-04  7.06824957e-01 -5.62863772e-04  7.07388045e-01" friction="1 0.5 0.01" solimp="0.95 0.95 0.01 0.5 6" solref="0.01 1" condim="6" margin="0.0"/>
                                            <joint name="joint_pinky_distal" pos="0.0 0.0 0.0" axis="1 0 0" ref="0" limited="true" range="-0.4 0.4" stiffness="5" springref="0.4" damping="0.5" solimplimit="0.95 0.95 0.01" solreflimit="0.01 1"/>
                                        </body>
                                    </body>
                                </body>
                            </body>
                        </body>
                    </body>
                </body>
            </body>
        </body>

    </worldbody>

    <actuator>
        <position  name="joint0" joint="joint0" ctrlrange="-6.28 6.28" kp="1000"/>
        <position  name="joint1" joint="joint1" ctrlrange="-3.14 3.14" kp="1000"/>
        <position  name="joint2" joint="joint2" ctrlrange="-3.14 3.14" kp="1000"/>
        <position  name="joint3" joint="joint3" ctrlrange="-6.28 6.28" kp="1000"/>
        <position  name="joint4" joint="joint4" ctrlrange="-6.28 6.28" kp="1000"/>
        <position  name="joint5" joint="joint5" ctrlrange="-6.28 6.28" kp="1000"/>
      
        <motor  name="joint_thumb" joint="joint_thumb" ctrlrange="-100 100"/>
        <motor  name="joint_thumb_distal" joint="joint_thumb_distal" ctrlrange="-100 100"/>
        <motor  name="joint_index" joint="joint_index" ctrlrange="-100 100"/>
        <motor  name="joint_index_distal" joint="joint_index_distal" ctrlrange="-100 100"/>
        <motor  name="joint_pinky" joint="joint_pinky" ctrlrange="-100 100"/>
        <motor  name="joint_pinky_distal" joint="joint_pinky_distal" ctrlrange="-100 100"/>
    </actuator>
</mujoco>
